Workbook

Sheet README
A1: FP&A Practice Workbook - Weeks 1 to 6
A2: Stage 0 (Excel fluency) and Stage 1 (data hygiene) of your 6-month plan. All data is fictional.
B4: How to use this workbook
A5: 1 | C5: Work the tabs in order. Each drill tab says which week it belongs to and what to build.
A6: 2 | C6: Only type in YELLOW cells (or in the new tabs you are told to create). Everything else is data or checks.
A7: 3 | C7: Every drill has a CHECK block. It shows PASS when your answer matches the control total, 'Not yet' when it does not, '-' when blank.
A8: 4 | C8: Control totals are like the trial balance you reconcile to at work: they tell you IF you are right, not HOW. Don't reverse-engineer them.
A9: 5 | C9: Build it yourself first. Afterwards you can ask Claude to run data-cleaning-for-excel or pivot-table-builder on the same data and compare.
A10: 6 | C10: Bring the file back at the end of week 3 and week 6 for grading against the pass criteria.
B12: Colour legend
B13: Yellow fill | C13: You type or build here
B14: Blue text | C14: Hardcoded input (a number someone typed)
B15: Black text | C15: Formula on the same sheet
B16: Green text | C16: Formula that links to another sheet
B17: Grey fill | C17: Control total (given, do not edit)
B19: Tab map
B20: Lookups | C20: Product master list. Used by Drills 1B and 1D.
B21: Transactions | C21: 1,168 clean sales lines for 2025. Source for Drills 1A and 1B.
B22: Drill 1 - SUMIFS | C22: Weeks 1-2. Month x product sales summary with SUMIFS.
B23: Drill 1 - Lookups+Refs | C23: Weeks 2-3. XLOOKUP, IFNA and the $ (mixed reference) grid.
B24: Raw GL Export | C24: Weeks 4-5. A deliberately messy expense ledger export. Never edit this tab.
B25: Drill 2 - Cleaning | C25: Weeks 4-5. Instructions and checks for your Clean and Change Log tabs.
B26: Budget | C26: 2025 annual expense budget by cost centre.
B27: Drill 3 - Pivot | C27: Week 6. Which cost centre overspent most? Pivot + SUMIFS, reconciled.
B28: Progress Log | C28: Record your status. Paste it back to Claude at each checkpoint.
B30: Keyboard drill (week 1): type x when you can do it without the mouse
B31: Ctrl + Arrow | C31: Jump to the edge of a data block
B32: Ctrl + Shift + Arrow | C32: Select to the edge of a data block
B33: F2 | C33: Edit the active cell (see its formula references coloured)
B34: F4 (while editing) | C34: Cycle $A$1 -> A$1 -> $A1 -> A1
B35: Ctrl + PgUp / PgDn | C35: Move between sheets
B36: Ctrl + D / Ctrl + R | C36: Fill down / fill right from the first cell of a selection
B37: Ctrl + T | C37: Turn a range into an Excel Table
B38: Ctrl + ` (backtick) | C38: Toggle formula view
B39: Ctrl + [ | C39: Jump to the cells a formula uses (precedents)

Sheet Lookups
A1: Lookups - Product master
A2: Reference data. Source: fictional, created for this exercise.
A4: Product code | B4: Product name | C4: Category | D4: List price
A5: P-100 | B5: Laptop Standard | C5: Hardware | D5: 850
A6: P-200 | B6: Laptop Pro | C6: Hardware | D6: 1450
A7: P-300 | B7: Support Plan | C7: Services | D7: 120
A8: P-400 | B8: Office Licence | C8: Software | D8: 95
A9: P-500 | B9: Installation | C9: Services | D9: 60

Sheet Transactions
A1: Date | B1: Invoice | C1: Product | D1: Region | E1: Qty | F1: Unit price | G1: Discount | H1: Amount | I1: Category
A2: 45658 | B2: INV-10063 | C2: P-100 | D2: Central | E2: 4 | F2: 850 | G2: 0 | H2: 3400
A3: 45658 | B3: INV-10069 | C3: P-300 | D3: Central | E3: 11 | F3: 120 | G3: 0 | H3: 1320
A4: 45659 | B4: INV-10038 | C4: P-300 | D4: Central | E4: 12 | F4: 120 | G4: 0 | H4: 1440
A5: 45660 | B5: INV-10062 | C5: P-100 | D5: West | E5: 14 | F5: 850 | G5: 0 | H5: 11900
A6: 45661 | B6: INV-10056 | C6: P-500 | D6: East | E6: 9 | F6: 60 | G6: 0.1 | H6: 486
A7: 45661 | B7: INV-10058 | C7: P-300 | D7: East | E7: 4 | F7: 120 | G7: 0.05 | H7: 456
A8: 45661 | B8: INV-10059 | C8: P-100 | D8: Central | E8: 12 | F8: 850 | G8: 0 | H8: 10200
A9: 45661 | B9: INV-10073 | C9: P-100 | D9: North | E9: 5 | F9: 850 | G9: 0.1 | H9: 3825
A10: 45662 | B10: INV-10009 | C10: P-500 | D10: North | E10: 10 | F10: 60 | G10: 0 | H10: 600
A11: 45662 | B11: INV-10041 | C11: P-500 | D11: West | E11: 17 | F11: 60 | G11: 0 | H11: 1020
A12: 45663 | B12: INV-10047 | C12: P-200 | D12: West | E12: 13 | F12: 1450 | G12: 0 | H12: 18850
A13: 45663 | B13: INV-10049 | C13: P-300 | D13: West | E13: 6 | F13: 120 | G13: 0 | H13: 720
... A1169: 46019 | B1169: INV-11144 | C1169: P-400 | D1169: East | E1169: 11 | F1169: 95 | G1169: 0 | H1169: 1045

Sheet Drill 1 - SUMIFS
A1: Drill 1A - Month x Product sales with SUMIFS (weeks 1-2)
A2: Source: Transactions tab. Amounts in $.
A3: Task: fill B6:M10 with ONE formula typed in B6 and copied across and down (Ctrl+R, Ctrl+D). Use SUMIFS on Transactions with the product in column A and the month start date in row 5: date >= month start AND date < EDATE(month start,1). Then fill the totals in column N and row 11 with SUM.
A5: Product \ Month | B5: 45658 | C5: 45689 | D5: 45717 | E5: 45748 | F5: 45778 | G5: 45809 | H5: 45839 | I5: 45870 | J5: 45901 | K5: 45931 | L5: 45962 | M5: 45992 | N5: Total
A6: P-100
A7: P-200
A8: P-300
A9: P-400
A10: P-500
A11: Total
A13: CHECK
A14: Check | B14: Your cell | C14: Control total | D14: Result
A15: Grand total (N11) | B15: =N11 -> 0 | C15: 5961678 | D15: =IF(ISBLANK(N11),"-",IF(ABS(N11-C15)<0.01,"PASS","Not yet")) -> -
A16: P-100, Jan-25 (B6) | B16: =B6 -> 0 | C16: 149685 | D16: =IF(ISBLANK(B6),"-",IF(ABS(B6-C16)<0.01,"PASS","Not yet")) -> -
A17: P-300, Jun-25 (G8) | B17: =G8 -> 0 | C17: 25752 | D17: =IF(ISBLANK(G8),"-",IF(ABS(G8-C17)<0.01,"PASS","Not yet")) -> -
A18: P-500, Dec-25 (M10) | B18: =M10 -> 0 | C18: 13725 | D18: =IF(ISBLANK(M10),"-",IF(ABS(M10-C18)<0.01,"PASS","Not yet")) -> -
A19: P-200 full year (N7) | B19: =N7 -> 0 | C19: 3296140 | D19: =IF(ISBLANK(N7),"-",IF(ABS(N7-C19)<0.01,"PASS","Not yet")) -> -
A20: Sep-25 all products (J11) | B20: =J11 -> 0 | C20: 614869 | D20: =IF(ISBLANK(J11),"-",IF(ABS(J11-C20)<0.01,"PASS","Not yet")) -> -
A21: Grid total = source total | B21: =N11 -> 0 | C21: =SUM(Transactions!$H$2:$H$1169) -> 5961678 | D21: =IF(ISBLANK(B21),"-",IF(ABS(B21-C21)<0.01,"PASS","Not yet")) -> Not yet
A23: Control totals: computed from the Transactions data when this workbook was generated.
A24: Pass criteria: all checks PASS; B6:M10 hold one identical formula (select B6:M10, F5 > Special > Row differences finds nothing); rebuilt from blank in under 30 minutes.

Sheet Drill 1 - Lookups+Refs
A1: Drills 1B-1D - Lookups, IFNA and mixed references (weeks 2-3)
A2: Build every answer with formulas, never typed values.
A4: 1B. Category column
A5: On the Transactions tab, fill column I (Category) with XLOOKUP from the Lookups tab: =XLOOKUP([@Product], Lookups!$A$5:$A$9, Lookups!$C$5:$C$9). Because it is an Excel Table, one formula fills the whole column.
A7: Category | B7: Lines (yours) | C7: Control | D7: Result | E7: Sales (yours) | F7: Control | G7: Result
A8: Hardware | B8: =COUNTIF(Transactions!$I$2:$I$1169,A8) -> 0 | C8: 455 | D8: =IF(B8=0,"-",IF(B8=C8,"PASS","Not yet")) -> - | F8: 5325812.5 | G8: =IF(ISBLANK(E8),"-",IF(ABS(E8-F8)<0.01,"PASS","Not yet")) -> -
A9: Services | B9: =COUNTIF(Transactions!$I$2:$I$1169,A9) -> 0 | C9: 480 | D9: =IF(B9=0,"-",IF(B9=C9,"PASS","Not yet")) -> - | F9: 415095 | G9: =IF(ISBLANK(E9),"-",IF(ABS(E9-F9)<0.01,"PASS","Not yet")) -> -
A10: Software | B10: =COUNTIF(Transactions!$I$2:$I$1169,A10) -> 0 | C10: 233 | D10: =IF(B10=0,"-",IF(B10=C10,"PASS","Not yet")) -> - | F10: 220770.5 | G10: =IF(ISBLANK(E10),"-",IF(ABS(E10-F10)<0.01,"PASS","Not yet")) -> -
A11: Column E: write a SUMIFS on the Category column yourself. Columns B-D count your XLOOKUP results automatically.
A13: 1C. IFNA: codes that may not exist
A14: Return the product name for each code. If the code is not in the master list, show exactly: Check: not found. Use IFNA (or XLOOKUP's if_not_found argument), NOT IFERROR, so other errors still show.
A15: Code to look up | B15: Product name | F15: Your note
A16: P-300
A17: P-100
A18: P-600
A19: P-500
A20: p-200
A21: P-400
A22: P-200
A23: P-10O
A25: Check | B25: Yours | C25: Control | D25: Result
A26: Count of 'Check: not found' | B26: =COUNTIF(B16:B23,"Check: not found") -> 0 | C26: 3 | D26: =IF(COUNTA(B16:B23)=0,"-",IF(B26=C26,"PASS","Not yet")) -> -
A27: Think: which not-found codes are genuinely missing, and which are dirty data (spaces, letter O for zero)? Write your answer in F16.
A29: 1D. Mixed references ($) - price x volume grid
A30: Fill C33:H37 with ONE formula typed in C33 and copied to the whole block: revenue = unit price (column B) x units (row 32) x (1 - discount in C31). You will need $B33, C$32 and $C$31. If you copy it and any cell is wrong, the $ are in the wrong place.
B31: Discount | C31: 0.05
B32: Price \ Units | C32: 50 | D32: 100 | E32: 150 | F32: 200 | G32: 250 | H32: 300
B33: 60
B34: 95
B35: 120
B36: 850
B37: 1450
A39: Check | B39: Yours | C39: Control | D39: Result
A40: Grid total | B40: =SUM(C33:H37) -> 0 | C40: 2568562.5 | D40: =IF(ISBLANK(B40),"-",IF(ABS(B40-C40)<0.01,"PASS","Not yet")) -> Not yet
A41: Bottom-right (H37) | B41: =H37 -> 0 | C41: 413250 | D41: =IF(ISBLANK(B41),"-",IF(ABS(B41-C41)<0.01,"PASS","Not yet")) -> Not yet
A42: Grid total at 10% discount | C42: 2433375 | D42: =IF(ISBLANK(B42),"-",IF(ABS(B42-C42)<0.01,"PASS","Not yet")) -> -
A43: Last check: change C31 to 10%, type the new grid total into B42 as =SUM(C33:H37), and see PASS. Then set C31 back to 5%. This is why inputs live in their own cell.

Sheet Raw GL Export
A1: ACME TRADING LTD - GL DETAIL EXPORT - FY2025
A2: Run by: SYSTEM Printed: 06/01/2026 07:14
A4: Posting Date | B4: Doc No | C4: Vendor Code | D4: Vendor | E4: Cost Centre | F4: GL Account | G4: Description | H4: Amount
A5: 01/01/2025 | B5: JE500023 | C5: 123 | D5: Office World Ltd | E5: hr | F5: 6500 Recruitment | G5: Recruitment Jan | H5: 1643.99
A6: 2025-01-01 | B6: JE500035 | C6: 01011 | D6: FastFreight | E6: it | F6: 6410 Security | G6: Security Jan | H6: 982.10
A7: 1 Jan 2025 | B7: JE500038 | C7: 00456 | D7: CloudHost Inc | E7: Sales & Mktg | F7: 6210 Travel | G7: Travel Jan | H7: $4,434.54
A8: 45659 | B8: JE500016 | C8: 04040 | D8: SecureNet | E8: it | F8: 6400 Cloud hosting | G8: Cloud hosting Jan | H8: 377.55
A9: 02.01.2025 | B9: JE500029 | C9: 00456 | D9: CloudHost Inc | E9: I.T. | F9: 6410 Security | G9: Security Jan | H9: 502.5
A10: 03/01/2025 | B10: JE500003 | C10: 01011 | D10: FastFreight | E10: Ops | F10: 6310 Utilities | G10: Utilities Jan | H10: 5,261.88
A11: 2025-01-03 | B11: JE500017 | C11: 06006 | D11: Legal Partners LLP | E11: it | F11: 6410 Security | G11: Security Jan | H11: 923.58
A12: 3 Jan 2025 | B12: JE500051 | C12: 123 | D12: Office World Ltd | E12: I.T. | F12: 6410 Security | G12: Security Jan | H12: 1,354.60
A13: 45661 | B13: JE500010 | C13: 00456 | D13: CloudHost Inc | E13: IT | F13: 6400 Cloud hosting | G13: Cloud hosting Jan | H13: $3,845.06
A14: 05.01.2025 | B14: JE500040 | C14: 00456 | D14: CloudHost Inc | E14: I.T. | F14: 6410 Security | G14: Security Jan | H14: 5,028.87
A15: 06/01/2025 | B15: JE500030 | C15: 03003 | D15: Printwise | E15: SALES | F15: 6200 Advertising | G15: Advertising Jan | H15: 8363.38
A16: 2025-01-07 | B16: JE500020 | C16: 04040 | D16: SecureNet | E16: it | F16: 6410 Security | G16: Security Jan | H16: 3,254.96
A17: 7 Jan 2025 | B17: JE500033 | C17: 05555 | D17: Travel Desk | E17: SALES | F17: 6210 Travel | G17: Travel Jan | H17: 2403.94
A18: 45665 | B18: JE500021 | C18: 02020 | D18: TalentFind Agency | E18: finance | F18: 6110 Bank charges | G18: Bank charges Jan | H18: 3,807.02
A19: 08.01.2025 | B19: JE500041 | C19: 4040 | D19: SecureNet | E19: it | F19: 6410 Security | G19: Security Jan | H19: $4,456.19
A20: 09/01/2025 | B20: JE500005 | C20: 06006 | D20: Legal Partners LLP | E20: SALES | F20: 6200 Advertising | G20: Advertising Jan | H20: 4,444.48
A21: 2025-01-09 | B21: JE500007 | C21: 05555 | D21: Travel Desk | E21: Fin. | F21: 6100 Audit fees | G21: Audit fees Jan | H21: 1475.29
A22: 9 Jan 2025 | B22: JE500012 | C22: 00789 | D22: City Power | E22: Operations | F22: 6300 Freight | G22: Freight Jan | H22: 3,466.46
A23: 45667 | B23: JE500002 | C23: 01011 | D23: FastFreight | E23: finance | F23: 6110 Bank charges | G23: Bank charges Jan | H23: 556.79
A24: 45667 | B24: JE500002 | C24: 01011 | D24: FastFreight | E24: finance | F24: 6110 Bank charges | G24: Bank charges Jan | H24: 556.79
A25: 10/01/2025 | B25: JE500018 | C25: 01011 | D25: FastFreight | E25: Sales | F25: 6210 Travel | G25: Travel Jan | H25: $5,686.79
A26: 2025-01-11 | B26: JE500043 | C26: 2020 | D26: TalentFind Agency | E26: IT | F26: 6400 Cloud hosting | G26: Cloud hosting Jan | H26: 1,630.73
A27: 12 Jan 2025 | B27: JE500008 | C27: 05555 | D27: Travel Desk | E27: Human Resources | F27: 6500 Recruitment | G27: Recruitment Jan | H27: 3503.06
A28: 45669 | B28: JE500032 | C28: 05555 | D28: Travel Desk | E28: HR | F28: 6500 Recruitment | G28: Recruitment Jan | H28: 2,876.00
A29: 13.01.2025 | B29: JE500013 | C29: 00456 | D29: CloudHost Inc | E29: HR | F29: 6510 Training | G29: Training Jan | H29: 329.8
A30: 16/01/2025 | B30: JE500050 | C30: 00456 | D30: CloudHost Inc | E30: hr | F30: 6510 Training | G30: Training Jan | H30: 3,476.98
A31: 2025-01-17 | B31: JE500001 | C31: 04040 | D31: SecureNet | E31: Finance | F31: 6100 Audit fees | G31: Audit fees Jan | H31: $1,432.45
A32: 18 Jan 2025 | B32: JE500024 | C32: 00456 | D32: CloudHost Inc | E32: finance | F32: 6110 Bank charges | G32: Bank charges Jan | H32: 1,491.87
A33: 45675 | B33: JE500026 | C33: 456 | D33: CloudHost Inc | E33: Sales & Mktg | F33: 6210 Travel | G33: Travel Jan | H33: 5345.8
A34: 18.01.2025 | B34: JE500027 | C34: 01011 | D34: FastFreight | E34: hr | F34: 6510 Training | G34: Training Jan | H34: 696.91
A35: 18/01/2025 | B35: JE500042 | C35: 03003 | D35: Printwise | E35: FINANCE | F35: 6100 Audit fees | G35: Audit fees Jan | H35: 3836.65
A36: 2025-01-18 | B36: JE500045 | C36: 00123 | D36: Office World Ltd | E36: Ops | F36: 6300 Freight | G36: Freight Jan | H36: (339.13)
A37: 18 Jan 2025 | B37: JE500049 | C37: 06006 | D37: Legal Partners LLP | E37: Sales | F37: 6210 Travel | G37: Travel Jan | H37: $6,505.89
A38: 45676 | B38: JE500019 | C38: 01011 | D38: FastFreight | E38: Sales | F38: 6210 Travel | G38: Travel Jan | H38: 3,254.79
A39: 20.01.2025 | B39: JE500011 | C39: 05555 | D39: Travel Desk | E39: Sales | F39: 6200 Advertising | G39: Advertising Jan | H39: 1685.98
A40: 20/01/2025 | B40: JE500022 | C40: 4040 | D40: SecureNet | E40: hr | F40: 6500 Recruitment | G40: Recruitment Jan | H40: 1,508.91
A41: 2025-01-20 | B41: JE500044 | C41: 00456 | D41: CloudHost Inc | E41: Sales | F41: 6210 Travel | G41: Travel Jan | H41: 2521.04
...

Sheet Drill 2 - Cleaning
A1: Drill 2 - Clean the GL export (weeks 4-5)
A2: Source: Raw GL Export tab. Do not edit the raw tab.
A4: 1. Part A (formulas, week 4): create two new tabs named exactly Clean and Change Log.
A5: 2. Clean tab: one header row in A1:I1 = Posting Date | Doc No | Vendor Code | Vendor | Cost Centre | GL Account | Description | Amount | Flag. Data from row 2, nothing below it.
A6: 3. Remove: the report title lines, repeated header rows, blank rows, 'Subtotal' rows, and exact duplicate rows.
A7: 4. Dates: convert all to real dates. The export is DAY-FIRST (look for a value like 25/03/2025 to prove it).
A8: 5. Amounts: real numbers. (300.00) and 300.00- are negatives. Strip $, commas, spaces and non-breaking spaces (CHAR(160)).
A9: 6. Vendor Code: text with 5 digits and leading zeros kept (123 must become 00123). Vendor: trim spaces incl. CHAR(160).
A10: 7. Cost Centre: map every variant to one of Finance, Sales, Operations, IT, HR. Log each mapping.
A11: 8. Doc No appearing twice with DIFFERENT amounts: keep both, write 'Check: duplicate Doc No' in Flag. Do not delete.
A12: 9. Change Log tab: Rule | Rows or cells affected | Example old value | New value. Finish with rows in / rows out.
A13: 10. Part B (Power Query, week 5): repeat the whole clean in Power Query (Data > From Table/Range or From Sheet), load it to a tab named Clean PQ, and confirm it gives the same checks.
A15: CHECK (reads your Clean tab once it exists)
A16: Check | B16: Yours | C16: Control | D16: Result
A17: Rows in Clean (excl. header) | B17: =IFERROR(COUNTA(INDIRECT("Clean!B2:B5000")),0) -> 0 | C17: 571 | D17: =IF(B17=0,"-",IF(ABS(B17-C17)<0.01,"PASS","Not yet")) -> -
A18: Total Amount | B18: =IFERROR(SUM(INDIRECT("Clean!H2:H5000")),0) -> 0 | C18: 1863767.6 | D18: =IF(B17=0,"-",IF(ABS(B18-C18)<0.01,"PASS","Not yet")) -> -
A19: Amounts still stored as text | B19: =IFERROR(SUMPRODUCT(--ISTEXT(INDIRECT("Clean!H2:H5000"))),0) -> 0 | C19: 0 | D19: =IF(B17=0,"-",IF(ROUND(B19,0)=C19,"PASS","Not yet")) -> -
A20: Dates still stored as text | B20: =IFERROR(SUMPRODUCT(--ISTEXT(INDIRECT("Clean!A2:A5000"))),0) -> 0 | C20: 0 | D20: =IF(B17=0,"-",IF(ROUND(B20,0)=C20,"PASS","Not yet")) -> -
A21: Rows flagged 'Check: duplicate Doc No' | B21: =IFERROR(COUNTIF(INDIRECT("Clean!I2:I5000"),"Check: duplicate Doc No"),0) -> 0 | C21: 4 | D21: =IF(B17=0,"-",IF(ROUND(B21,0)=C21,"PASS","Not yet")) -> -
A22: Distinct cost centres used | B22: =IFERROR(SUMPRODUCT((INDIRECT("Clean!E2:E5000")<>"")/COUNTIF(INDIRECT("Clean!E2:E5000"),INDIRECT("Clean!E2:E5000")&"")),0) -> 0 | C22: 5 | D22: =IF(B17=0,"-",IF(ROUND(B22,0)=C22,"PASS","Not yet")) -> -
A23: Total Amount - Finance | B23: =IFERROR(SUMIFS(INDIRECT("Clean!H2:H5000"),INDIRECT("Clean!E2:E5000"),"Finance"),0) -> 0 | C23: 158110.59 | D23: =IF(B17=0,"-",IF(ABS(B23-C23)<0.01,"PASS","Not yet")) -> -
A24: Total Amount - Sales | B24: =IFERROR(SUMIFS(INDIRECT("Clean!H2:H5000"),INDIRECT("Clean!E2:E5000"),"Sales"),0) -> 0 | C24: 740689.7 | D24: =IF(B17=0,"-",IF(ABS(B24-C24)<0.01,"PASS","Not yet")) -> -
A25: Total Amount - Operations | B25: =IFERROR(SUMIFS(INDIRECT("Clean!H2:H5000"),INDIRECT("Clean!E2:E5000"),"Operations"),0) -> 0 | C25: 511324.12 | D25: =IF(B17=0,"-",IF(ABS(B25-C25)<0.01,"PASS","Not yet")) -> -
A26: Total Amount - IT | B26: =IFERROR(SUMIFS(INDIRECT("Clean!H2:H5000"),INDIRECT("Clean!E2:E5000"),"IT"),0) -> 0 | C26: 344501.12 | D26: =IF(B17=0,"-",IF(ABS(B26-C26)<0.01,"PASS","Not yet")) -> -
A27: Total Amount - HR | B27: =IFERROR(SUMIFS(INDIRECT("Clean!H2:H5000"),INDIRECT("Clean!E2:E5000"),"HR"),0) -> 0 | C27: 109142.1 | D27: =IF(B17=0,"-",IF(ABS(B27-C27)<0.01,"PASS","Not yet")) -> -
A29: The raw tab has 600 rows including title lines. Your Change Log must explain every row that did not make it to Clean.
A30: Control totals: computed from the underlying ledger when this workbook was generated (think of them as the trial balance).
A31: Checks use INDIRECT so they stay quiet (show -) until your Clean tab exists. Name the tab exactly 'Clean' and start data in row 2.

Sheet Budget
A1: 2025 expense budget by cost centre
A2: Source: fictional board-approved budget, created for this exercise. $.
A4: Cost Centre | B4: FY2025 budget
A5: Finance | B5: 168000
A6: Sales | B6: 652000
A7: Operations | B7: 522000
A8: IT | B8: 313000
A9: HR | B9: 106000
A10: Total | B10: =SUM(B5:B9) -> 1761000

Sheet Drill 3 - Pivot
A1: Drill 3 - Which cost centre overspent most? (week 6)
A2: Source: your Clean tab + Budget tab.
A3: 1) Insert a native PivotTable from your Clean tab (Ctrl+T first so it grows) on a new tab named Pivot: Rows = Cost Centre, Values = Sum of Amount. Link its grand total into B16 (type = then click the pivot's grand total cell). 2) Fill C7:C11 with SUMIFS on the Clean tab. 3) Fill D7:E11 with variance and variance %. 4) Answer the question in B19.
A6: Cost Centre | B6: Budget | C6: Actual (SUMIFS) | D6: Variance (Actual - Budget) | E6: Variance %
A7: Finance | B7: =INDEX(Budget!$B$5:$B$9,MATCH($A7,Budget!$A$5:$A$9,0)) -> 168000
A8: Sales | B8: =INDEX(Budget!$B$5:$B$9,MATCH($A8,Budget!$A$5:$A$9,0)) -> 652000
A9: Operations | B9: =INDEX(Budget!$B$5:$B$9,MATCH($A9,Budget!$A$5:$A$9,0)) -> 522000
A10: IT | B10: =INDEX(Budget!$B$5:$B$9,MATCH($A10,Budget!$A$5:$A$9,0)) -> 313000
A11: HR | B11: =INDEX(Budget!$B$5:$B$9,MATCH($A11,Budget!$A$5:$A$9,0)) -> 106000
A12: Total | B12: =SUM(B7:B11) -> 1761000
A14: Check | B14: Yours | C14: Control | D14: Result
A15: Actual total (C12) | B15: =C12 -> 0 | C15: 1863767.6 | D15: =IF(ISBLANK(C12),"-",IF(ABS(C12-C15)<0.01,"PASS","Not yet")) -> -
A16: Pivot grand total (link it) | C16: 1863767.6 | D16: =IF(ISBLANK(B16),"-",IF(ABS(B16-C16)<0.01,"PASS","Not yet")) -> -
A17: Pivot total = SUMIFS total | B17: =B16 -> 0 | C17: =C12 -> 0 | D17: =IF(OR(ISBLANK(B16),ISBLANK(C12)),"-",IF(ABS(B16-C12)<0.01,"PASS","Not yet")) -> -
A19: Answer: which cost centre overspent most, by how much ($ and %)?
A20: Is the biggest overspend in $ the same as the biggest in %? Which would you report first, and why?
A22: Pass criteria: all checks PASS; pivot and SUMIFS agree to the cent; the answer names the cost centre, the $ variance and the %.

Sheet Progress Log
A1: Progress log
A2: Update after each session. Paste this table back to Claude at each checkpoint.
A4: Competency | B4: Week(s) | C4: Status | D4: Evidence (tab / date) | E4: Next action
A5: Keyboard drill | B5: 1 | C5: Not started
A6: 1A SUMIFS grid | B6: 1-2 | C6: Not started
A7: 1B XLOOKUP category | B7: 2 | C7: Not started
A8: 1C IFNA | B8: 2-3 | C8: Not started
A9: 1D Mixed references | B9: 3 | C9: Not started
A10: Checkpoint 1 (grade) | B10: 3 | C10: Not started
A11: 2A Clean with formulas | B11: 4 | C11: Not started
A12: 2B Clean with Power Query | B12: 5 | C12: Not started
A13: 3 Pivot + reconciliation | B13: 6 | C13: Not started
A14: Checkpoint 2 (grade) | B14: 6 | C14: Not started
